I'm sorry, but an uncaught exception occurred.

While running game code:
  File "game/script.rpy", line 1046, in script
    b @ mask_cracked angry "H-how dare you? Dissenters, all of you! Your god Baphomet commands you to stop!"
Exception: Image 'baphomet mask_cracked' does not accept attributes 'angry'.

-- Full Traceback ------------------------------------------------------------

Full traceback:
  File "game/script.rpy", line 1046, in script
    b @ mask_cracked angry "H-how dare you? Dissenters, all of you! Your god Baphomet commands you to stop!"
  File "C:\Users\ste41\Downloads\renpy-8.0.3-sdk\renpy\ast.py", line 921, in execute
    renpy.exports.say(who, what, *args, **kwargs)
  File "C:\Users\ste41\Downloads\renpy-8.0.3-sdk\renpy\exports.py", line 1373, in say
    who(what, *args, **kwargs)
  File "C:\Users\ste41\Downloads\renpy-8.0.3-sdk\renpy\character.py", line 1206, in __call__
    old_attr_state = self.handle_say_attributes(False, interact)
  File "C:\Users\ste41\Downloads\renpy-8.0.3-sdk\renpy\character.py", line 1041, in handle_say_attributes
    if self.resolve_say_attributes(predicting, temporary_attrs):
  File "C:\Users\ste41\Downloads\renpy-8.0.3-sdk\renpy\character.py", line 986, in resolve_say_attributes
    renpy.exports.show(show_image)
  File "C:\Users\ste41\Downloads\renpy-8.0.3-sdk\renpy\exports.py", line 686, in show
    if not base.find_target() and renpy.config.missing_show:
  File "C:\Users\ste41\Downloads\renpy-8.0.3-sdk\renpy\display\image.py", line 414, in find_target
    self.target = target._duplicate(a)
  File "C:\Users\ste41\Downloads\renpy-8.0.3-sdk\renpy\display\core.py", line 397, in _duplicate
    args.extraneous()
  File "C:\Users\ste41\Downloads\renpy-8.0.3-sdk\renpy\display\core.py", line 265, in extraneous
    raise Exception("Image '{}' does not accept attributes '{}'.".format(
Exception: Image 'baphomet mask_cracked' does not accept attributes 'angry'.

Windows-10-10.0.19043 AMD64
Ren'Py 8.0.3.22090809
Azazel 1.0
Fri Nov  4 17:22:11 2022
